<?xml version="1.0" encoding="UTF-8"?>
<testng-results skipped="0" failed="1" total="2" passed="1">
  <reporter-output>
    <line>
      <![CDATA[<span style="color:#16A05D"><H1>hello</H1>]]>
    </line>
  </reporter-output>
  <suite name="Suite1" duration-ms="79" started-at="2017-03-15T14:27:35Z" finished-at="2017-03-15T14:27:35Z">
    <groups>
    </groups>
    <test name="test1" duration-ms="79" started-at="2017-03-15T14:27:35Z" finished-at="2017-03-15T14:27:35Z">
      <class name="com.reportngdemo.NewTest">
        <test-method status="PASS" signature="add01()[pri:0, instance:com.reportngdemo.NewTest@1936f0f5]" name="add01" duration-ms="30" started-at="2017-03-15T22:27:35Z" finished-at="2017-03-15T22:27:35Z">
          <reporter-output>
            <line>
              <![CDATA[<span style="color:#16A05D"><H1>hello</H1>]]>
            </line>
          </reporter-output>
        </test-method> <!-- add01 -->
        <test-method status="FAIL" signature="add02()[pri:0, instance:com.reportngdemo.NewTest@1936f0f5]" name="add02" duration-ms="3" started-at="2017-03-15T22:27:35Z" finished-at="2017-03-15T22:27:35Z">
          <exception class="java.lang.AssertionError">
            <message>
              <![CDATA[expected [1] but found [2]]]>
            </message>
            <full-stacktrace>
              <![CDATA[java.lang.AssertionError: expected [1] but found [2]
	at org.testng.Assert.fail(Assert.java:94)
	at org.testng.Assert.failNotEquals(Assert.java:513)
	at org.testng.Assert.assertEqualsImpl(Assert.java:135)
	at org.testng.Assert.assertEquals(Assert.java:116)
	at org.testng.Assert.assertEquals(Assert.java:389)
	at org.testng.Assert.assertEquals(Assert.java:399)
	at com.reportngdemo.NewTest.add02(NewTest.java:16)
	at sun.reflect.NativeMethodAccessorImpl.invoke0(Native Method)
	at sun.reflect.NativeMethodAccessorImpl.invoke(Unknown Source)
	at sun.reflect.DelegatingMethodAccessorImpl.invoke(Unknown Source)
	at java.lang.reflect.Method.invoke(Unknown Source)
	at org.testng.internal.MethodInvocationHelper.invokeMethod(MethodInvocationHelper.java:86)
	at org.testng.internal.Invoker.invokeMethod(Invoker.java:643)
	at org.testng.internal.Invoker.invokeTestMethod(Invoker.java:820)
	at org.testng.internal.Invoker.invokeTestMethods(Invoker.java:1128)
	at org.testng.internal.TestMethodWorker.invokeTestMethods(TestMethodWorker.java:129)
	at org.testng.internal.TestMethodWorker.run(TestMethodWorker.java:112)
	at org.testng.TestRunner.privateRun(TestRunner.java:782)
	at org.testng.TestRunner.run(TestRunner.java:632)
	at org.testng.SuiteRunner.runTest(SuiteRunner.java:366)
	at org.testng.SuiteRunner.runSequentially(SuiteRunner.java:361)
	at org.testng.SuiteRunner.privateRun(SuiteRunner.java:319)
	at org.testng.SuiteRunner.run(SuiteRunner.java:268)
	at org.testng.SuiteRunnerWorker.runSuite(SuiteRunnerWorker.java:52)
	at org.testng.SuiteRunnerWorker.run(SuiteRunnerWorker.java:86)
	at org.testng.TestNG.runSuitesSequentially(TestNG.java:1244)
	at org.testng.TestNG.runSuitesLocally(TestNG.java:1169)
	at org.testng.TestNG.run(TestNG.java:1064)
	at org.testng.remote.RemoteTestNG.run(RemoteTestNG.java:113)
	at org.testng.remote.RemoteTestNG.initAndRun(RemoteTestNG.java:206)
	at org.testng.remote.RemoteTestNG.main(RemoteTestNG.java:177)
]]>
            </full-stacktrace>
          </exception> <!-- java.lang.AssertionError -->
          <reporter-output>
          </reporter-output>
        </test-method> <!-- add02 -->
      </class> <!-- com.reportngdemo.NewTest -->
    </test> <!-- test1 -->
  </suite> <!-- Suite1 -->
</testng-results>
